Backup failed for Site library.com. Database or site_config.json may be corrupted
Traceback (most recent call last):
  File "apps/frappe/frappe/commands/site.py", line 711, in backup
    odb = scheduled_backup(
  File "apps/frappe/frappe/utils/backups.py", line 529, in scheduled_backup
    odb = new_backup(
  File "apps/frappe/frappe/utils/backups.py", line 581, in new_backup
    odb.get_backup(older_than, ignore_files, force=force)
  File "apps/frappe/frappe/utils/backups.py", line 190, in get_backup
    self.take_dump()
  File "apps/frappe/frappe/utils/backups.py", line 378, in take_dump
    frappe.throw(
  File "apps/frappe/frappe/__init__.py", line 522, in throw
    msgprint(
  File "apps/frappe/frappe/__init__.py", line 490, in msgprint
    _raise_exception()
  File "apps/frappe/frappe/__init__.py", line 442, in _raise_exception
    raise raise_exception(msg)
frappe.exceptions.ExecutableNotFound: pg_dump not found in PATH! This is required to take a backup.

